2024-07-11 16:34:36,981 - __thread 1__ - ERROR - the 6 problem 1 attempt failed��
2024-07-11 16:34:39,163 - __thread 0__ - ERROR - the 0 problem 1 attempt failed��
2024-07-11 16:34:39,553 - __thread 3__ - ERROR - the 10 problem 1 attempt failed��
2024-07-11 16:34:41,620 - __thread 5__ - ERROR - the 20 problem 1 attempt failed��
2024-07-11 16:34:42,861 - __thread 4__ - ERROR - the 13 problem 1 attempt failed��
2024-07-11 16:34:43,093 - __thread 2__ - ERROR - the 8 problem 1 attempt failed��
2024-07-11 16:34:47,872 - __thread 0__ - ERROR - the 0 problem 2 attempt failed��
2024-07-11 16:34:50,575 - __thread 1__ - ERROR - the 6 problem 2 attempt failed��
2024-07-11 16:34:50,699 - __thread 5__ - ERROR - the 20 problem 2 attempt failed��
2024-07-11 16:34:52,286 - __thread 3__ - ERROR - the 10 problem 2 attempt failed��
2024-07-11 16:34:53,231 - __thread 4__ - ERROR - the 13 problem 2 attempt failed��
2024-07-11 16:34:55,113 - __thread 2__ - ERROR - the 8 problem 2 attempt failed��
2024-07-11 16:34:56,075 - __thread 0__ - ERROR - the 0 problem 3 attempt failed��
2024-07-11 16:34:56,075 - __thread 0__ - ERROR - ======message======:

2024-07-11 16:34:56,075 - __thread 0__ - ERROR - [Errno 13] Permission denied: './tmp\\data.xlsx'

2024-07-11 16:34:56,076 - __thread 0__ - ERROR - Traceback (most recent call last):
  File "C:\Users\Admin\PycharmProjects\pythonProject\doubao\multi_thread_frame\multi_thread_test_v3.py", line 381, in basic_run
    write_excel(excel_dic, result_list, row_num)
  File "C:\Users\Admin\PycharmProjects\pythonProject\doubao\multi_thread_frame\multi_thread_test_v3.py", line 331, in write_excel
    excel_dic["workbook"].save(excel_dic["excel_path"])
  File "C:\Users\Admin\PycharmProjects\pythonProject\venv\Lib\site-packages\openpyxl\workbook\workbook.py", line 386, in save
    save_workbook(self, filename)
  File "C:\Users\Admin\PycharmProjects\pythonProject\venv\Lib\site-packages\openpyxl\writer\excel.py", line 291, in save_workbook
    archive = ZipFile(filename, 'w', ZIP_DEFLATED, allowZip64=True)
              ^^^^^^^^^^^^^^^^^^^^^^^^^^^^^^^^^^^^^^^^^^^^^^^^^^^^^
  File "C:\Program Files\WindowsApps\PythonSoftwareFoundation.Python.3.12_3.12.1264.0_x64__qbz5n2kfra8p0\Lib\zipfile\__init__.py", line 1331, in __init__
    self.fp = io.open(file, filemode)
              ^^^^^^^^^^^^^^^^^^^^^^^
PermissionError: [Errno 13] Permission denied: './tmp\\data.xlsx'


2024-07-11 16:34:58,546 - __thread 1__ - ERROR - the 6 problem 3 attempt failed��
2024-07-11 16:34:58,546 - __thread 1__ - ERROR - ======message======:

2024-07-11 16:34:58,546 - __thread 1__ - ERROR - [Errno 13] Permission denied: './tmp\\data.xlsx'

2024-07-11 16:34:58,547 - __thread 1__ - ERROR - Traceback (most recent call last):
  File "C:\Users\Admin\PycharmProjects\pythonProject\doubao\multi_thread_frame\multi_thread_test_v3.py", line 381, in basic_run
    write_excel(excel_dic, result_list, row_num)
  File "C:\Users\Admin\PycharmProjects\pythonProject\doubao\multi_thread_frame\multi_thread_test_v3.py", line 331, in write_excel
    excel_dic["workbook"].save(excel_dic["excel_path"])
  File "C:\Users\Admin\PycharmProjects\pythonProject\venv\Lib\site-packages\openpyxl\workbook\workbook.py", line 386, in save
    save_workbook(self, filename)
  File "C:\Users\Admin\PycharmProjects\pythonProject\venv\Lib\site-packages\openpyxl\writer\excel.py", line 291, in save_workbook
    archive = ZipFile(filename, 'w', ZIP_DEFLATED, allowZip64=True)
              ^^^^^^^^^^^^^^^^^^^^^^^^^^^^^^^^^^^^^^^^^^^^^^^^^^^^^
  File "C:\Program Files\WindowsApps\PythonSoftwareFoundation.Python.3.12_3.12.1264.0_x64__qbz5n2kfra8p0\Lib\zipfile\__init__.py", line 1331, in __init__
    self.fp = io.open(file, filemode)
              ^^^^^^^^^^^^^^^^^^^^^^^
PermissionError: [Errno 13] Permission denied: './tmp\\data.xlsx'
